Workbook
Name destinos: 'EGR 1-copiar en word 0 EGR'!#REF!
Name destinos: 'EGR2 2--copiar en word 1 EGR'!#REF!
Name no: 'EGR 1-copiar en word 0 EGR'!#REF!
Name no: 'EGR2 2--copiar en word 1 EGR'!#REF!
Name tratamientos: 'EGR 1-copiar en word 0 EGR'!#REF!
Name tratamientos: 'EGR2 2--copiar en word 1 EGR'!#REF!

Sheet INDICACIONES
A1: 1 | B1: Rellenar mediciones aéreas
A2: 2 | B2: Rellenar mediciones subterráneas
A3: 3 | B3: ajustar mediciones por TTMM
A4: 4 | B4: chequear la suma tota por TTMM
A6: 6 | B6: ajustar columna derecha de items y eliminar filas con valores cero
A7: 7 | B7: ¿seguro que está todo OK?
A8: 8 | B8: hacer una copia de seguridad
A9: 9 | B9: entonces a preparar pot TTMM:
B10: Se copia la hoja tantas veces como ttmm hay
B11: Se borran las columnas de mediciones

Sheet 1.- datos aéreo
A1: APOYOS
B2: DATOS POR TIPO DE APOYO
A3: TIPO DE APOYO | B3: Peso | E3: Excavación | H3: Hormigonado | I3: BASTON AISLADOR | J3: CADENA SUS | K3: CADENA AM
A4: FL-PAS | B4: 93 | E4: 32.5 | H4: 37.4 | I4: 3 | J4: 0 | K4: 3
A5: FL | B5: 90 | E5: 32 | H5: 36.16 | I5: 3 | J5: 0 | K5: 3
A6: SUS-AL | B6: 40 | E6: 28 | H6: 31.64 | I6: 3 | J6: 3 | K6: 0
A7: ANC-ANG | B7: 70 | E7: 31 | H7: =+E7*H5/E5 -> 35.03 | I7: 6 | J7: 0 | K7: 6
B9: PROCESO
A10: 1 | B10: Se traen los datos de apoyos de la carpeta de tablas
A11: 2 | B11: se añade la parte verde
A12: 3 | B12: se obtienen los totales por TTMM | U12: tmm 1 | V12: ttmm2 | W12: ttmm3
A13: paso 1.- DISPONIBLE EN LA CARPETA DE #TABLAS DE CADA AP | R13: paso 2.- SE ASIGNA A CADA APOYO CON LA TABLA DE ARRIBA Y SE OBTIENENLSO TOTALES | U13: paso 3.- REPARTO POR TTMM | X13: herrajes 30 kV por apoyo DX LA280 | AA13: herrajes 220 kV por apoyo DX LA280 | AD13: herrajes 220 kV por apoyo TX LA510
A14: PUNTO/NUMERO APOYO | B14: TRAMO DE LÍNEA | E14: TIPO APOYO | H14: Tensión Línea | I14: ALTURA CRUCETA INFERIOR (m) | J14: ALTURA TOTAL DEL APOYO (m) | K14: OCUPACIÓN PERMANENTE (m2) | L14: OCUPACIÓN TEMPORAL (m2) | M14: X U.T.M. ETRS89 HUSO 30 | N14: Y U.T.M. ETRS89 HUSO 30 | O14: Término municipal | P14: Provincia | Q14: Comunidad autónoma | R14: PESO (Tn) | S14: Exv (m3) | T14: Hor (m3) | U14: PESO (Tn) | V14: Exv (m3) | W14: Hor (m3) | X14: CADENAS DE SUSPENSION | Y14: CADENAS DE AMARRE | Z14: BASTONES | AA14: CADENAS DE SUSPENSION | AB14: CADENAS DE AMARRE | AC14: BASTONES | AD14: CADENAS DE SUSPENSION | AE14: CADENAS DE AMARRE | AF14: BASTONES
Q16: TOTALES | R16: =SUM(R15:R15) -> 0 | S16: =SUM(S15:S15) -> 0 | T16: =SUM(T15:T15) -> 0 | U16: =SUM(U15:U15) -> 0 | V16: =SUM(V15:V15) -> 0 | W16: =SUM(W15:W15) -> 0 | X16: =SUM(X15:X15) -> 0 | Y16: =SUM(Y15:Y15) -> 0 | ... AF16: =SUM(AF15:AF15) -> 0
R18: TEST | X18: CADENAS DE SUSPENSION | Y18: CADENAS DE AMARRE | Z18: BASTONES | AA18: CADENAS DE SUSPENSION | AB18: CADENAS DE AMARRE | AC18: BASTONES | AD18: CADENAS DE SUSPENSION | AE18: CADENAS DE AMARRE | AF18: BASTONES
R19: =+R16/U16 -> #DIV/0! | S19: =+S16/V16 -> #DIV/0! | T19: =+T16/W16 -> #DIV/0! | X19: herrajes 30 kV por apoyo DX LA280 | AA19: herrajes 220 kV por apoyo DX LA280 | AD19: herrajes 220 kV por apoyo TX LA510
A20: CABLE AÉREO Y HERRAJES
B21: PROCESO
A22: 1 | B22: Se traen los datos LONGITUDES DE TRAMO Y TTMM de la carpeta de tablas | K22: la280 | L22: 0.973
A23: 2 | B23: se añade la parte verde | K23: opgw | L23: 0.68
A24: 3 | B24: se obtienen los totales por TTMM | K24: la510 | L24: 1.6
A26: TRAMO | B26: ORIGEN | C26: X UTM ETRS89 HUSO31 | D26: Y UTM ETRS89 HUSO31 | E26: FINAL | F26: X UTM ETRS89 HUSO31 | G26: Y UTM ETRS89 HUSO31 | H26: TIPO | I26: Nº CIRC | J26: LONGITUD DEL TRAMO (m) | L26: ORIGEN | M26: DESCRIPCION | N26: ORIGEN X ETRS89 HUSO 30 | O26: ORIGEN Y ETRS89 HUSO 30 | P26: TTMM | Q26: PROVINCIA | R26: COMUNIDAD
A27: 1 | B27: PO/SE XXX | C27: 472975.95 | D27: 4388875.8 | E27: PF/SE SONREUS | F27: 472666.03 | G27: 4388926 | H27: SUBTERRÁNEO | I27: 1 | J27: 427 | L27: PO/SE XXX | N27: =C27 -> 472975.95 | O27: =D27 -> 4388875.8 | P27: PALMA | Q27: MALLORCA | R27: ISLAS BALEARES
A28: LONGITUDES TOTALES (m) | J28: =J27 -> 427 | L28: PF/SE SONREUS | N28: 472666.03 | O28: 4388926 | P28: PALMA | Q28: MALLORCA | R28: ISLAS BALEARES
A36: % terminales | B36: 0.08
A37: TRAMO | B37: ORIGEN | C37: X UTM ETRS89 HUSO31 | D37: Y UTM ETRS89 HUSO31 | E37: FINAL | F37: X UTM ETRS89 HUSO31 | G37: Y UTM ETRS89 HUSO31 | H37: TIPO | I37: Nº CIRC | J37: LONGITUD DEL TRAMO (m) | K37: LONGITUD EN EL TTMM DE ARRATZUA - UBARRUNDIA (Álava) | L37: LONGITUD EN EL TTMM DE ZIGOITIA (Álava)
A38: 1 | B38: PO-1 | C38: 474495.75 | D38: 4388125.9 | E38: BIF-1 | H38: SUBTERRÁNEO | I38: 1 | J38: 3.31 | N38: L1 | O38: =J38+J40 -> 2192.64
A39: 2 | B39: PO-2 | C39: 474491.42 | D39: 4388135 | E39: BIF-1 | H39: SUBTERRÁNEO | I39: 2 | J39: 13.36 | N39: L2 | O39: =J39+J40 -> 2202.69
A40: 3 | B40: BIF-1 | E40: PF/ SE XXX | F40: 472979.58 | G40: 4388842.7 | H40: SUBTERRÁNEO | I40: 4 | J40: 2189.33 | K40: 0 | N40: LT | O40: =SUM(O38:O39) -> 4395.33
A41: LONGITUD TOTAL EJE TRAMO SUBTERRÁNEO 30 kV (m) | J41: =SUM(J38:J40) -> 2206 | K41: 0 | L41: =#REF! -> #REF! | O41: =O40/2 -> 2197.665
A42: LONGITUDES TOTALES (m) | J42: =J41 -> 2206 | K42: =+K41 -> 0 | L42: =+L41 -> #REF!
Q46: LONG | R46: =+#REF! -> #REF! | S46: =+#REF! -> #REF! | T46: =+#REF! -> #REF! | U46: =+#REF! -> #REF! | V46: =+#REF! -> #REF! | W46: =+#REF! -> #REF! | X46: =+#REF! -> #REF! | Y46: =+#REF! -> #REF! | ... AA46: =+#REF! -> #REF! | AB46: =SUM(R46:AA46) -> #REF!
Q47: % | R47: =+R46/$AB$46 -> #REF! | S47: =+S46/$AB$46 -> #REF! | T47: =+T46/$AB$46 -> #REF! | U47: =+U46/$AB$46 -> #REF! | V47: =+V46/$AB$46 -> #REF! | W47: =+W46/$AB$46 -> #REF! | X47: =+X46/$AB$46 -> #REF! | Y47: =+Y46/$AB$46 -> #REF! | ... AA47: =+AA46/$AB$46 -> #REF! | AB47: =SUM(R47:AA47) -> #REF!
B48: 1 hay, 0 no hay | E48: esta columna no puede estar vacia | H48: =+K37 -> LONGITUD EN EL TTMM DE ARRATZUA - UBARRUNDIA (Álava) | I48: =+L37 -> LONGITUD EN EL TTMM DE ZIGOITIA (Álava) | J48: =+M37 -> 0 | K48: nº subcondcutores | L48: nº circuitos | M48: total cables del circuito | N48: peso cable (kg/m) | O48: MEDICION
A49: nº apoyos | AB49: =+O49-SUM(R49:AA49) -> 0
A50: Conductor tipo LA280 cctos 30 kV | P50: =+'PRESUPUESTO P'!C64 -> kg | AB50: =+O50-SUM(R50:AA50) -> 0
A51: Conductor tipo LA280 cctos 220 kV | P51: =+'PRESUPUESTO P'!C65 -> kg | AB51: =+O51-SUM(R51:AA51) -> 0
A52: Conductor tipo LA510 cctos 220 kV | P52: =+'PRESUPUESTO P'!C66 -> kg | AB52: =+O52-SUM(R52:AA52) -> 0
A53: Cable compuesto OPGW cctos 30 kV | P53: =+'PRESUPUESTO P'!C67 -> m | AB53: =+O53-SUM(R53:AA53) -> 0
A54: Cable compuesto OPGW cctos 220 kV | P54: =+'PRESUPUESTO P'!C68 -> m | AB54: =+O54-SUM(R54:AA54) -> 0
...

Sheet 2.- datos subt
A1: LINEA 30 KV SUBTERRANEA-1 CCTO | C1: TTMM 1 | D1: TTMM 2 | E1: TTMM 3
A2: nº de cables aislados 30 kV/240mm2 | B2: 6 | E2: rellenar a mano las cedas verdes sin crear referencias circulares
A3: nº de cables aislados 30 kV/630 mm2 | B3: 6 | E3: rellenar a mano las cedas verdes sin crear referencias circulares
A4: nº de cables FO | B4: 2 | C4: =+'1.- datos aéreo'!K37 -> LONGITUD EN EL TTMM DE ARRATZUA - UBARRUNDIA (Álava) | D4: =+'1.- datos aéreo'!L37 -> LONGITUD EN EL TTMM DE ZIGOITIA (Álava) | F4: test
A5: Cajas empalmes FO 30 kV | B5: =SUM(C5:E5) -> 0 | F5: =+B5-SUM(C5:E5) -> 0
A6: longitud zanja 30 kV | B6: =+'1.- datos aéreo'!J41 -> 2206 | C6: =+'1.- datos aéreo'!K41 -> 0 | F6: =+B6-SUM(C6:E6) -> 2206
A7: longitud perforación 30 kV | B7: =+B8*110/2 -> 0 | C7: =+C8*110/2 -> 0 | D7: =+D8*110/2 -> 0 | F7: =+B7-SUM(C7:E7) -> 0 | H7: 4 PHD
A8: nº de pozos | B8: 0 | C8: 0 | D8: 0 | F8: =+B8-SUM(C8:E8) -> 0 | H8: 2 pozos por cada perforacion | J8: revisad el listado de cruces en tramos subt
A9: longiud cable 30 kV entre terminales 240 mm2 | B9: =+B7*1.1+(B6-B7)*1.05 -> 2316.3 | C9: =+C7*1.1+(C6-C7)*1.05 -> 0 | D9: =+D7*1.1+(D6-D7)*1.05 -> 0 | F9: =+B9-SUM(C9:E9) -> 2316.3
A10: longiud cable 30 kV entre terminales 630 mm2 | B10: =+B7*1.1+(B6-B7)*1.05 -> 2316.3 | C10: =+C8*1.1+(C7-C8)*1.05 -> 0 | D10: =+D8*1.1+(D7-D8)*1.05 -> 0 | F10: =+B10-SUM(C10:E10) -> 2316.3
A11: longiud cable 30 kV total 240 mm2 | B11: ='1.- datos aéreo'!J38*3+'1.- datos aéreo'!J39*3+'1.- datos aéreo'!J40*6 -> 13185.99 | C11: =+C9*$B$3 -> 0 | D11: =+D9*$B$3 -> 0 | F11: =+B11-SUM(C11:E11) -> 13185.99
A12: longiud cable 30 kV total 630 mm2 | B12: ='1.- datos aéreo'!J38*3+'1.- datos aéreo'!J39*3+'1.- datos aéreo'!J40*6 -> 13185.99 | C12: =+C11*$B$3 -> 0 | D12: =+D11*$B$3 -> 0 | F12: =+B12-SUM(C12:E12) -> 13185.99
A13: longiud cable FO CCTO 30 kV total | B13: =B9*B4 -> 4632.6 | C13: =+C11/$B$3*$B$4 -> 0 | D13: =+D11/$B$3*$B$4 -> 0 | F13: =+B13-SUM(C13:E13) -> 4632.6
A14: CE empalmes 30 kV | B14: 0 | C14: =+INT(C9/700)-1 -> -1 | F14: =+B14-SUM(C14:E14) -> 1
A15: Nº empalmes 30 kV | B15: =+B14*$B$3 -> 0 | C15: =+C14*$B$3 -> -6 | D15: =+D14*$B$3 -> 0 | F15: =+B15-SUM(C15:E15) -> 6
A16: nº tramos subterraneos 30 Kv independientes | B16: 1 | C16: 1 | D16: 0 | F16: =+B16-SUM(C16:E16) -> 0
A17: terminales 30 kV/240mm2 | B17: =B2 -> 6 | C17: =+C15*9 -> -54 | D17: =+D15*9 -> 0 | F17: =+B17-SUM(C17:E17) -> 60
A18: terminales 30 kV/630mm2 | B18: =B3 -> 6 | C18: =+C16*9 -> 9 | D18: =+D16*9 -> 0 | F18: =+B18-SUM(C18:E18) -> -3
A19: cajas puesta a tierra 30 kV | B19: 0 | C19: 0 | D19: 0 | F19: =+B19-SUM(C19:E19) -> 0
B20: E/KM | C20: =+C6/(C14+1) -> #DIV/0! | D20: =+D6/(D14+1) -> 0
A21: LINEA 220 KV SUBTERRANEA-1 CCTO
A22: nº de cables aislados 220 kV | B22: 3
A23: nº de cables FO ctto 220 kV | B23: 3
A24: Cajas empalmes FO 220 kV | B24: 0
A25: longitud zanja 220 kV | B25: 430.47
A26: longitud perforación 220 kV | B26: 0
A27: nº de pozos | B27: 0 | H27: 2 pozos por cada perforacion | J27: =+J8 -> revisad el listado de cruces en tramos subt
A28: longiud cable 220 kV entre terminales | B28: =B25*1.05 -> 451.9935
A29: longiud cable 220 kV total | B29: =B28*B22+10+10 -> 1375.9805
A30: longiud cable FO CCTO 220 kV total | B30: =B28*B23+200 -> 1555.9805
A31: CE empalmes 220 kV | B31: 0
A32: Nº empalmes 220 kV | B32: 0
A33: nº tramos subterraneos 220 kV indep | B33: 1
A34: terminales 220 kV | B34: 6
A35: cajas puesta a tierra 220 kV | B35: 3 | C35: 3 y 3
A36: apoyos PAS
A37: autoválvulas 220 kV

Sheet Cruces
A1: Núm. | B1: Denominación | C1: Organismo | D1: X U.T.M. ETRS89 HUSO 30 | E1: Y U.T.M. ETRS89 HUSO 30 | F1: Término municipal | G1: Provincia | K1: Paralelismo Nº | L1: Denominación | M1: Organismo | N1: PUNTO INICIAL-FINAL | O1: X U,T,M, ETRS89 HUSO 30 | P1: Y U,T,M, ETRS89 HUSO 30 | Q1: Término municipal | R1: Provincia
A2: CR-01 | B2: Tubería distribución agua | D2: 474305.25 | E2: 4388413.4 | F2: Marratxi | G2: Mallorca | K2: PA-01 | L2: Tubería distribución agua | N2: PA-01 PI | O2: 474433.61 | P2: 4388142.7 | Q2: Marratxi | R2: Mallorca
A3: CR-02 | B3: Carretera Ma-2031 | D3: 474148.21 | E3: 4388651.2 | F3: Marratxi | G3: Mallorca | N3: CR-01 | O3: 474305.25 | P3: 4388413.4 | Q3: Marratxi | R3: Mallorca
A4: CR-03 | B4: Cauce | D4: 473383.91 | E4: 4388960 | F4: Palma | G4: Mallorca | K4: PA-02 | L4: Gasoducto ramal 1 Gasoducto ramal 2 | M4: Redexis Gas Transporte, S.L. | N4: PA-01 PI | O4: 474433.61 | P4: 4388142.7 | Q4: Marratxi | R4: Mallorca
A5: CR-04 | B5: Cauce | D5: 473355.32 | E5: 4388988.5 | F5: Palma | G5: Mallorca | N5: PA-02 PF | O5: 473253.86 | P5: 4389071.5 | Q5: Palma | R5: Mallorca
A6: CR-05 | B6: Línea eléctrica aérea | C6: REDEIA | D6: 473320.58 | E6: 4389023.2 | F6: Palma | G6: Mallorca | K6: PA-03 | L6: Gasoducto ramal 2 Gasoducto ramal 3 | M6: Redexis Gas Transporte, S.L. | N6: PA-02 PF | O6: 473253.86 | P6: 4389071.5 | Q6: Palma | R6: Mallorca
A7: CR-06 | B7: Línea eléctrica aérea | D7: 473200.95 | E7: 4389018.9 | F7: Palma | G7: Mallorca | Q7: Palma | R7: Mallorca
A11: CR-07 | B11: Gasoducto | C11: Redexis Gas Transporte, S.L. | D11: 472878.58 | E11: 4388794.7 | F11: Palma | G11: Mallorca | K11: PA-04 | L11: Gasoducto ramal 2 Gasoducto ramal 3 | M11: Redexis Gas Transporte, S.L. | Q11: Palma | R11: Mallorca
A12: CR-08 | B12: Camí Son Reus | D12: 472846.71 | E12: 4388794.9 | F12: Palma | G12: Mallorca | N12: PA-04 PF | O12: 472863.01 | P12: 4388784.1 | Q12: Palma | R12: Mallorca
A13: CR-09 | B13: Gasoducto | C13: Redexis Gas Transporte, S.L. | D13: 472834.85 | E13: 4388807 | F13: Palma | G13: Mallorca
A14: CR-10 | B14: Línea eléctrica | D14: 472734.25 | E14: 4388909.3 | F14: Palma | G14: Mallorca

Sheet PRESUPUESTO P
H1: =+'1.- datos aéreo'!K37 -> LONGITUD EN EL TTMM DE ARRATZUA - UBARRUNDIA (Álava) | I1: =+'1.- datos aéreo'!L37 -> LONGITUD EN EL TTMM DE ZIGOITIA (Álava) | J1: =+'1.- datos aéreo'!M37 -> 0
A2: CAPÍTULO 1. LÍNEA SUBTERRÁNEA | H2: TTMM 1 | I2: TTMM 2 | J2: TTMM 3
A3: CAPÍTULO 1.1 MATERIALES LÍNEA SUBTERRÁNEA | H3: =+'1.- datos aéreo'!K42 -> 0 | I3: =+'1.- datos aéreo'!L42 -> #REF! | J3: =+'1.- datos aéreo'!M42 -> 0 | K3: =SUM(H3:J3) -> #REF! | L3: LONG EJE
A4: Partida | B4: Concepto | C4: Ud. | D4: Cantidad | E4: Precio Ud | F4: Importe (€) | H4: =+H3/$K$3 -> #REF! | I4: =+I3/$K$3 -> #REF! | J4: =+J3/$K$3 -> #REF! | K4: =SUM(H4:J4) -> #REF! | L4: % LONG EJE
A5: 1.1.1 | B5: Cable aislado 30 kV/240 mm2 | C5: m | D5: =+'2.- datos subt'!B11 -> 13185.99 | E5: 4 | F5: =D5*E5 -> 52743.96 | G5: =+D5-SUM(H5:J5) -> 13185.99 | H5: =+'2.- datos subt'!C11 -> 0 | I5: =+'2.- datos subt'!D11 -> 0 | J5: =+'2.- datos subt'!E11 -> 0
A6: 1.1.1 | B6: Cable aislado 30 kV/630 mm2 | C6: m | D6: =+'2.- datos subt'!B12 -> 13185.99 | E6: 6.5 | F6: =D6*E6 -> 85708.935 | G6: =+D6-SUM(H6:J6) -> 13185.99 | H6: =+'2.- datos subt'!C13 -> 0 | I6: =+'2.- datos subt'!D13 -> 0 | J6: =+'2.- datos subt'!E13 -> 0
A7: 1.1.2 | B7: Cable aislado 220 kV | C7: m | D7: =+'2.- datos subt'!B28 -> 451.9935 | E7: 120 | F7: =D7*E7 -> 54239.22 | G7: =+D7-SUM(H7:J7) -> 451.9935 | H7: 0 | I7: 0 | J7: 0
A8: 1.1.3 | B8: Terminales 30 kV 240 mm2 | C8: ud | D8: =+'2.- datos subt'!B17 -> 6 | E8: =ROUNDUP(160*240/630,0) -> 61 | F8: =D8*E8 -> 366 | G8: =+D8-SUM(H8:J8) -> 5 | H8: =+'2.- datos subt'!C16 -> 1 | I8: =+'2.- datos subt'!D16 -> 0 | J8: =+'2.- datos subt'!E16 -> 0 | K8: =2.3*1.05*6 -> 14.49
A9: 1.1.3 | B9: Terminales 30 kV 630 mm2 | C9: ud | D9: =+'2.- datos subt'!B18 -> 6 | E9: 160 | F9: =D9*E9 -> 960 | G9: =+D9-SUM(H9:J9) -> -3 | H9: =+'2.- datos subt'!C18 -> 9 | I9: =+'2.- datos subt'!D18 -> 0 | J9: =+'2.- datos subt'!E18 -> 0
A10: 1.1.4 | B10: Terminales 220 kV | C10: ud | D10: =+'2.- datos subt'!B34 -> 6 | E10: 7000 | F10: =D10*E10 -> 42000 | G10: =+D10-SUM(H10:J10) -> 6 | H10: 0 | I10: 0 | J10: 0
A11: 1.1.5 | B11: Autoválvulas 220 kV | C11: ud | D11: =+'2.- datos subt'!B37 -> 0 | E11: 3300 | F11: =D11*E11 -> 0 | G11: =+D11-SUM(H11:J11) -> 0 | H11: 0 | I11: 0 | J11: 0
A12: 1.1.6 | B12: Cámaras de empalmes 30 kV | C12: ud | D12: =+'2.- datos subt'!B14 -> 0 | E12: 300 | F12: =D12*E12 -> 0 | G12: =+D12-SUM(H12:J12) -> 1 | H12: =+'2.- datos subt'!C14 -> -1 | I12: =+'2.- datos subt'!D14 -> 0 | J12: =+'2.- datos subt'!E14 -> 0
A13: 1.1.7 | B13: Cámaras de empalmes 220 kV | C13: ud | D13: =+'2.- datos subt'!B31 -> 0 | E13: 950 | F13: =D13*E13 -> 0 | G13: =+D13-SUM(H13:J13) -> 0 | H13: 0 | I13: 0 | J13: 0
A14: 1.1.8 | B14: Empalmes 30 kV | C14: ud | D14: =+'2.- datos subt'!B15 -> 0 | E14: 180 | F14: =D14*E14 -> 0 | G14: =+D14-SUM(H14:J14) -> 6 | H14: =+'2.- datos subt'!C15 -> -6 | I14: =+'2.- datos subt'!D15 -> 0 | J14: =+'2.- datos subt'!E15 -> 0
A15: 1.1.9 | B15: Empalmes 220 kV | C15: ud | D15: =+'2.- datos subt'!B32 -> 0 | E15: 5000 | F15: =D15*E15 -> 0 | G15: =+D15-SUM(H15:J15) -> 0 | H15: 0 | I15: 0 | J15: 0
A16: 1.1.10 | B16: Caja de puesta a tierra 30 kV | C16: ud | D16: =+'2.- datos subt'!B19 -> 0 | E16: 640 | F16: =D16*E16 -> 0 | G16: =+D16-SUM(H16:J16) -> 0 | H16: =+'2.- datos subt'!C19 -> 0 | I16: =+'2.- datos subt'!D19 -> 0 | J16: =+'2.- datos subt'!E19 -> 0
A17: 1.1.11 | B17: Caja de puesta a tierra 220 kV intemperie | C17: ud | D17: =+D18 -> 3 | E17: 3100 | F17: =D17*E17 -> 9300 | G17: =+D17-SUM(H17:J17) -> 3 | H17: 0 | I17: 0 | J17: 0
A18: 1.1.11 | B18: Caja de puesta a tierra 220 kV intemperie con descargador | C18: ud | D18: =+'2.- datos subt'!B35 -> 3 | E18: 3200 | F18: =D18*E18 -> 9600 | G18: =+D18-SUM(H18:J18) -> 3 | H18: 0 | I18: 0 | J18: 0
A19: 1.1.12 | B19: Pequeño material p.a.t pantallas | C19: ud | D19: 2 | E19: 1000 | F19: =D19*E19 -> 2000 | G19: =+D19-SUM(H19:J19) -> 0 | H19: 2 | I19: 0 | J19: 0
A20: 1.1.13 | B20: Cable comunicaciones FO ccto 30 kV | C20: m | D20: =+'2.- datos subt'!B9*'2.- datos subt'!B4 -> 4632.6 | E20: 1 | F20: =D20*E20 -> 4632.6 | G20: =+D20-SUM(H20:J20) -> 4632.6 | H20: =+'2.- datos subt'!C13 -> 0 | I20: =+'2.- datos subt'!D13 -> 0 | J20: =+'2.- datos subt'!E13 -> 0
A21: 1.1.14 | B21: Cable comunicaciones FO ccto 220 kV | C21: m | D21: =+'2.- datos subt'!B28*'2.- datos subt'!B23 -> 1355.9805 | E21: 1.2 | F21: =D21*E21 -> 1627.1766 | G21: =+D21-SUM(H21:J21) -> 1355.9805 | H21: 0 | I21: 0 | J21: 0
A22: 1.1.15 | B22: Cajas empalme FO ccto 30 kV | C22: ud | D22: =+'2.- datos subt'!B5 -> 0 | E22: 300 | F22: =D22*E22 -> 0 | G22: =+D22-SUM(H22:J22) -> 0 | H22: =+'2.- datos subt'!C5 -> 0 | I22: =+'2.- datos subt'!D5 -> 0 | J22: =+'2.- datos subt'!E5 -> 0
A23: 1.1.16 | B23: Cajas empalme FO ccto 220 kV | C23: ud | D23: =+'2.- datos subt'!B24 -> 0 | E23: 300 | F23: =D23*E23 -> 0 | G23: =+D23-SUM(H23:J23) -> 0 | H23: 0 | I23: 0 | J23: 0
A24: TOTAL CAPÍTULO 1.1.- | F24: =SUM(F5:F23) -> 263177.89
A26: CAPÍTULO 1.2. MONTAJE LÍNEA SUBTERRÁNEA
A27: Partida | B27: Concepto | C27: Ud. | D27: Cantidad | E27: Precio Ud | F27: Importe (€)
A28: 1.2.1 | B28: =+B5 -> Cable aislado 30 kV/240 mm2 | C28: =+C5 -> m | D28: =+D5 -> 13185.99 | E28: 1.1 | F28: =D28*E28 -> 14504.589 | G28: =+D28-SUM(H28:J28) -> 13185.99 | H28: =+H5 -> 0 | I28: =+I5 -> 0 | J28: =+J5 -> 0
A29: 1.2.2 | B29: =+B6 -> Cable aislado 30 kV/630 mm2 | C29: =+C6 -> m | D29: =+D6 -> 13185.99 | E29: 1.5 | F29: =D29*E29 -> 19778.985 | G29: =+D29-SUM(H29:J29) -> 13185.99 | H29: =+H6 -> 0 | I29: =+I6 -> 0 | J29: =+J6 -> 0
A30: 1.2.2 | B30: =+B7 -> Cable aislado 220 kV | C30: =+C7 -> m | D30: =+D7 -> 451.9935 | E30: 6.5 | F30: =D30*E30 -> 2937.9578 | G30: =+D30-SUM(H30:J30) -> 451.9935 | H30: =+H7 -> 0 | I30: =+I7 -> 0 | J30: =+J7 -> 0
A31: 1.2.3 | B31: =+B8 -> Terminales 30 kV 240 mm2 | C31: =+C8 -> ud | D31: =+D8 -> 6 | E31: =ROUNDUP(220*240/630,0) -> 84 | F31: =D31*E31 -> 504 | G31: =+D31-SUM(H31:J31) -> 5 | H31: =+H8 -> 1 | I31: =+I8 -> 0 | J31: =+J8 -> 0
A32: 1.2.3 | B32: =+B9 -> Terminales 30 kV 630 mm2 | C32: =+C9 -> ud | D32: =+D9 -> 6 | E32: 220 | F32: =D32*E32 -> 1320 | G32: =+D32-SUM(H32:J32) -> -3 | H32: =+H9 -> 9 | I32: =+I9 -> 0 | J32: =+J9 -> 0
A33: 1.2.4 | B33: =+B10 -> Terminales 220 kV | C33: =+C10 -> ud | D33: =+D10 -> 6 | E33: 2600 | F33: =D33*E33 -> 15600 | G33: =+D33-SUM(H33:J33) -> 6 | H33: =+H10 -> 0 | I33: =+I10 -> 0 | J33: =+J10 -> 0
A34: 1.2.5 | B34: =+B11 -> Autoválvulas 220 kV | C34: =+C11 -> ud | D34: =+D11 -> 0 | E34: 1300 | F34: =D34*E34 -> 0 | G34: =+D34-SUM(H34:J34) -> 0 | H34: =+H11 -> 0 | I34: =+I11 -> 0 | J34: =+J11 -> 0
A35: 1.2.6 | B35: =+B12 -> Cámaras de empalmes 30 kV | C35: =+C12 -> ud | D35: =+D12 -> 0 | E35: 400 | F35: =D35*E35 -> 0 | G35: =+D35-SUM(H35:J35) -> 1 | H35: =+H12 -> -1 | I35: =+I12 -> 0 | J35: =+J12 -> 0
A36: 1.2.7 | B36: =+B13 -> Cámaras de empalmes 220 kV | C36: =+C13 -> ud | D36: =+D13 -> 0 | E36: 3100 | F36: =D36*E36 -> 0 | G36: =+D36-SUM(H36:J36) -> 0 | H36: =+H13 -> 0 | I36: =+I13 -> 0 | J36: =+J13 -> 0
A37: 1.2.8 | B37: =+B14 -> Empalmes 30 kV | C37: =+C14 -> ud | D37: =+D14 -> 0 | E37: 300 | F37: =D37*E37 -> 0 | G37: =+D37-SUM(H37:J37) -> 6 | H37: =+H14 -> -6 | I37: =+I14 -> 0 | J37: =+J14 -> 0
A38: 1.2.9 | B38: =+B15 -> Empalmes 220 kV | C38: =+C15 -> ud | D38: =+D15 -> 0 | E38: 2500 | F38: =D38*E38 -> 0 | G38: =+D38-SUM(H38:J38) -> 0 | H38: =+H15 -> 0 | I38: =+I15 -> 0 | J38: =+J15 -> 0
A39: 1.2.10 | B39: =+B16 -> Caja de puesta a tierra 30 kV | C39: =+C16 -> ud | D39: =+D16 -> 0 | E39: 220 | F39: =D39*E39 -> 0 | G39: =+D39-SUM(H39:J39) -> 0 | H39: =+H16 -> 0 | I39: =+I16 -> 0 | J39: =+J16 -> 0
A40: 1.2.11 | B40: =+B17 -> Caja de puesta a tierra 220 kV intemperie | C40: =+C17 -> ud | D40: =+D18 -> 3 | E40: 800 | F40: =D40*E40 -> 2400 | G40: =+D40-SUM(H40:J40) -> 3 | H40: =+H17 -> 0 | I40: =+I17 -> 0 | J40: =+J17 -> 0
A41: 1.2.11 | B41: =+B18 -> Caja de puesta a tierra 220 kV intemperie con descargador | C41: =+C18 -> ud | D41: =+D18 -> 3 | E41: 900 | F41: =D41*E41 -> 2700 | G41: =+D41-SUM(H41:J41) -> 3 | H41: =+H18 -> 0 | I41: =+I18 -> 0 | J41: =+J18 -> 0
...

Sheet PRESUPUESTO  TTMM 1 UBARRUNDIA
A2: CAPÍTULO 1. LÍNEA SUBTERRÁNEA
A3: CAPÍTULO 1.1 MATERIALES LÍNEA SUBTERRÁNEA
A4: Partida | B4: Concepto | C4: Ud. | D4: Cantidad | E4: Precio Ud | F4: Importe (€)
A5: 1.1.1 | B5: Cable aislado 30 kV | C5: m | D5: =+'PRESUPUESTO P'!H5 -> 0 | E5: =+'PRESUPUESTO P'!E5 -> 4 | F5: =D5*E5 -> 0
A6: 1.1.2 | B6: Cable aislado 220 kV | C6: m | D6: =+'PRESUPUESTO P'!H7 -> 0 | E6: =+'PRESUPUESTO P'!E7 -> 120 | F6: =D6*E6 -> 0
A7: 1.1.3 | B7: Terminales 30 kV | C7: ud | D7: =+'PRESUPUESTO P'!H9 -> 9 | E7: =+'PRESUPUESTO P'!E9 -> 160 | F7: =D7*E7 -> 1440
A8: 1.1.4 | B8: Terminales 220 kV | C8: ud | D8: =+'PRESUPUESTO P'!H10 -> 0 | E8: =+'PRESUPUESTO P'!E10 -> 7000 | F8: =D8*E8 -> 0
A9: 1.1.5 | B9: Autoválvulas 220 kV | C9: ud | D9: =+'PRESUPUESTO P'!H11 -> 0 | E9: =+'PRESUPUESTO P'!E11 -> 3300 | F9: =D9*E9 -> 0
A10: 1.1.6 | B10: Cámaras de empalmes 30 kV | C10: ud | D10: =+'PRESUPUESTO P'!H12 -> -1 | E10: =+'PRESUPUESTO P'!E12 -> 300 | F10: =D10*E10 -> -300
A11: 1.1.7 | B11: Cámaras de empalmes 220 kV | C11: ud | D11: =+'PRESUPUESTO P'!H13 -> 0 | E11: =+'PRESUPUESTO P'!E13 -> 950 | F11: =D11*E11 -> 0
A12: 1.1.8 | B12: Empalmes 30 kV | C12: ud | D12: =+'PRESUPUESTO P'!H14 -> -6 | E12: =+'PRESUPUESTO P'!E14 -> 180 | F12: =D12*E12 -> -1080
A13: 1.1.9 | B13: Empalmes 220 kV | C13: ud | D13: =+'PRESUPUESTO P'!H15 -> 0 | E13: =+'PRESUPUESTO P'!E15 -> 5000 | F13: =D13*E13 -> 0
A14: 1.1.10 | B14: Caja de puesta a tierra 30 kV | C14: ud | D14: =+'PRESUPUESTO P'!H16 -> 0 | E14: =+'PRESUPUESTO P'!E16 -> 640 | F14: =D14*E14 -> 0
A15: 1.1.11 | B15: Caja de puesta a tierra 220 kV | C15: ud | D15: =+'PRESUPUESTO P'!H18 -> 0 | E15: =+'PRESUPUESTO P'!E18 -> 3200 | F15: =D15*E15 -> 0
A16: 1.1.12 | B16: Pequeño material p.a.t pantallas | C16: ud | D16: =+'PRESUPUESTO P'!H19 -> 2 | E16: =+'PRESUPUESTO P'!E19 -> 1000 | F16: =D16*E16 -> 2000
A17: 1.1.13 | B17: Cable comunicaciones FO ccto 30 kV | C17: m | D17: =+'PRESUPUESTO P'!H20 -> 0 | E17: =+'PRESUPUESTO P'!E20 -> 1 | F17: =D17*E17 -> 0
A18: 1.1.14 | B18: Cable comunicaciones FO ccto 220 kV | C18: m | D18: =+'PRESUPUESTO P'!H21 -> 0 | E18: =+'PRESUPUESTO P'!E21 -> 1.2 | F18: =D18*E18 -> 0
A19: 1.1.15 | B19: Cajas empalme FO FO ccto 30 kV | C19: ud | D19: =+'PRESUPUESTO P'!H22 -> 0 | E19: =+'PRESUPUESTO P'!E22 -> 300 | F19: =D19*E19 -> 0
A20: 1.1.16 | B20: Cajas empalme FO FO ccto 220 kV | C20: ud | D20: =+'PRESUPUESTO P'!H23 -> 0 | E20: =+'PRESUPUESTO P'!E23 -> 300 | F20: =D20*E20 -> 0
A21: TOTAL CAPÍTULO 1.1.- | F21: =SUM(F5:F20) -> 2060
A23: CAPÍTULO 1.2. MONTAJE LÍNEA SUBTERRÁNEA
A24: Partida | B24: Concepto | C24: Ud. | D24: Cantidad | E24: Precio Ud | F24: Importe (€)
A25: 1.2.1 | B25: =+B5 -> Cable aislado 30 kV | C25: =+C5 -> m | D25: =+D5 -> 0 | E25: =+'PRESUPUESTO P'!E28 -> 1.1 | F25: =D25*E25 -> 0
A26: 1.2.2 | B26: =+B6 -> Cable aislado 220 kV | C26: =+C6 -> m | D26: =+D6 -> 0 | E26: =+'PRESUPUESTO P'!E30 -> 6.5 | F26: =D26*E26 -> 0
A27: 1.2.3 | B27: =+B7 -> Terminales 30 kV | C27: =+C7 -> ud | D27: =+D7 -> 9 | E27: =+'PRESUPUESTO P'!E32 -> 220 | F27: =D27*E27 -> 1980
A28: 1.2.4 | B28: =+B8 -> Terminales 220 kV | C28: =+C8 -> ud | D28: =+D8 -> 0 | E28: =+'PRESUPUESTO P'!E33 -> 2600 | F28: =D28*E28 -> 0
A29: 1.2.5 | B29: =+B9 -> Autoválvulas 220 kV | C29: =+C9 -> ud | D29: =+D9 -> 0 | E29: =+'PRESUPUESTO P'!E34 -> 1300 | F29: =D29*E29 -> 0
A30: 1.2.6 | B30: =+B10 -> Cámaras de empalmes 30 kV | C30: =+C10 -> ud | D30: =+D10 -> -1 | E30: =+'PRESUPUESTO P'!E35 -> 400 | F30: =D30*E30 -> -400
A31: 1.2.7 | B31: =+B11 -> Cámaras de empalmes 220 kV | C31: =+C11 -> ud | D31: =+D11 -> 0 | E31: =+'PRESUPUESTO P'!E36 -> 3100 | F31: =D31*E31 -> 0
A32: 1.2.8 | B32: =+B12 -> Empalmes 30 kV | C32: =+C12 -> ud | D32: =+D12 -> -6 | E32: =+'PRESUPUESTO P'!E37 -> 300 | F32: =D32*E32 -> -1800
A33: 1.2.9 | B33: =+B13 -> Empalmes 220 kV | C33: =+C13 -> ud | D33: =+D13 -> 0 | E33: =+'PRESUPUESTO P'!E38 -> 2500 | F33: =D33*E33 -> 0
A34: 1.2.10 | B34: =+B14 -> Caja de puesta a tierra 30 kV | C34: =+C14 -> ud | D34: =+D14 -> 0 | E34: =+'PRESUPUESTO P'!E39 -> 220 | F34: =D34*E34 -> 0
A35: 1.2.11 | B35: =+B15 -> Caja de puesta a tierra 220 kV | C35: =+C15 -> ud | D35: =+D15 -> 0 | E35: =+'PRESUPUESTO P'!E41 -> 900 | F35: =D35*E35 -> 0
A36: 1.2.12 | B36: =+B16 -> Pequeño material p.a.t pantallas | C36: =+C16 -> ud | D36: =+D16 -> 2 | E36: =+'PRESUPUESTO P'!E42 -> 400 | F36: =D36*E36 -> 800
A37: 1.2.13 | B37: =+B17 -> Cable comunicaciones FO ccto 30 kV | C37: =+C17 -> m | D37: =+D17 -> 0 | E37: =+'PRESUPUESTO P'!E43 -> 1.9 | F37: =D37*E37 -> 0
A38: 1.2.14 | B38: =+B18 -> Cable comunicaciones FO ccto 220 kV | C38: =+C18 -> m | D38: =+D18 -> 0 | E38: =+'PRESUPUESTO P'!E44 -> 2.8 | F38: =D38*E38 -> 0
A39: 1.2.15 | B39: =+B19 -> Cajas empalme FO FO ccto 30 kV | C39: =+C19 -> ud | D39: =+D19 -> 0 | E39: =+'PRESUPUESTO P'!E45 -> 400 | F39: =D39*E39 -> 0
A40: 1.2.16 | B40: =+B20 -> Cajas empalme FO FO ccto 220 kV | C40: =+C20 -> ud | D40: =+D20 -> 0 | E40: =+'PRESUPUESTO P'!E46 -> 600 | F40: =D40*E40 -> 0
A41: TOTAL CAPÍTULO 1.2.- | F41: =SUM(F25:F40) -> 580
A43: CAPÍTULO 1.3. OBRA CIVIL LÍNEA SUBTERRÁNEA
...

Sheet PRESUPUESTO TTMM 2  ZIGOITIA
A2: CAPÍTULO 1. LÍNEA SUBTERRÁNEA
A3: CAPÍTULO 1.1 MATERIALES LÍNEA SUBTERRÁNEA
A4: Partida | B4: Concepto | C4: Ud. | D4: Cantidad | E4: Precio Ud | F4: Importe (€)
A5: 1.1.1 | B5: Cable aislado 30 kV | C5: m | D5: =+'PRESUPUESTO P'!I5 -> 0 | E5: =+'PRESUPUESTO P'!E5 -> 4 | F5: =D5*E5 -> 0
A6: 1.1.2 | B6: Cable aislado 220 kV | C6: m | D6: =+'PRESUPUESTO P'!I7 -> 0 | E6: =+'PRESUPUESTO P'!E7 -> 120 | F6: =D6*E6 -> 0
A7: 1.1.3 | B7: Terminales 30 kV | C7: ud | D7: =+'PRESUPUESTO P'!I9 -> 0 | E7: =+'PRESUPUESTO P'!E9 -> 160 | F7: =D7*E7 -> 0
A8: 1.1.4 | B8: Terminales 220 kV | C8: ud | D8: =+'PRESUPUESTO P'!I10 -> 0 | E8: =+'PRESUPUESTO P'!E10 -> 7000 | F8: =D8*E8 -> 0
A9: 1.1.5 | B9: Autoválvulas 220 kV | C9: ud | D9: =+'PRESUPUESTO P'!I11 -> 0 | E9: =+'PRESUPUESTO P'!E11 -> 3300 | F9: =D9*E9 -> 0
A10: 1.1.6 | B10: Cámaras de empalmes 30 kV | C10: ud | D10: =+'PRESUPUESTO P'!I12 -> 0 | E10: =+'PRESUPUESTO P'!E12 -> 300 | F10: =D10*E10 -> 0
A11: 1.1.7 | B11: Cámaras de empalmes 220 kV | C11: ud | D11: =+'PRESUPUESTO P'!I13 -> 0 | E11: =+'PRESUPUESTO P'!E13 -> 950 | F11: =D11*E11 -> 0
A12: 1.1.8 | B12: Empalmes 30 kV | C12: ud | D12: =+'PRESUPUESTO P'!I14 -> 0 | E12: =+'PRESUPUESTO P'!E14 -> 180 | F12: =D12*E12 -> 0
A13: 1.1.9 | B13: Empalmes 220 kV | C13: ud | D13: =+'PRESUPUESTO P'!I15 -> 0 | E13: =+'PRESUPUESTO P'!E15 -> 5000 | F13: =D13*E13 -> 0
A14: 1.1.10 | B14: Caja de puesta a tierra 30 kV | C14: ud | D14: =+'PRESUPUESTO P'!I16 -> 0 | E14: =+'PRESUPUESTO P'!E16 -> 640 | F14: =D14*E14 -> 0
A15: 1.1.11 | B15: Caja de puesta a tierra 220 kV | C15: ud | D15: =+'PRESUPUESTO P'!I18 -> 0 | E15: =+'PRESUPUESTO P'!E18 -> 3200 | F15: =D15*E15 -> 0
A16: 1.1.12 | B16: Pequeño material p.a.t pantallas | C16: ud | D16: =+'PRESUPUESTO P'!I19 -> 0 | E16: =+'PRESUPUESTO P'!E19 -> 1000 | F16: =D16*E16 -> 0
A17: 1.1.13 | B17: Cable comunicaciones FO ccto 30 kV | C17: m | D17: =+'PRESUPUESTO P'!I20 -> 0 | E17: =+'PRESUPUESTO P'!E20 -> 1 | F17: =D17*E17 -> 0
A18: 1.1.14 | B18: Cable comunicaciones FO ccto 220 kV | C18: m | D18: =+'PRESUPUESTO P'!I21 -> 0 | E18: =+'PRESUPUESTO P'!E21 -> 1.2 | F18: =D18*E18 -> 0
A19: 1.1.15 | B19: Cajas empalme FO FO ccto 30 kV | C19: ud | D19: =+'PRESUPUESTO P'!I22 -> 0 | E19: =+'PRESUPUESTO P'!E22 -> 300 | F19: =D19*E19 -> 0
A20: 1.1.16 | B20: Cajas empalme FO FO ccto 220 kV | C20: ud | D20: =+'PRESUPUESTO P'!I23 -> 0 | E20: =+'PRESUPUESTO P'!E23 -> 300 | F20: =D20*E20 -> 0
A21: TOTAL CAPÍTULO 1.1.- | F21: =SUM(F5:F20) -> 0
A23: CAPÍTULO 1.2. MONTAJE LÍNEA SUBTERRÁNEA
A24: Partida | B24: Concepto | C24: Ud. | D24: Cantidad | E24: Precio Ud | F24: Importe (€)
A25: 1.2.1 | B25: =+B5 -> Cable aislado 30 kV | C25: =+C5 -> m | D25: =+D5 -> 0 | E25: =+'PRESUPUESTO P'!E28 -> 1.1 | F25: =D25*E25 -> 0
A26: 1.2.2 | B26: =+B6 -> Cable aislado 220 kV | C26: =+C6 -> m | D26: =+D6 -> 0 | E26: =+'PRESUPUESTO P'!E30 -> 6.5 | F26: =D26*E26 -> 0
A27: 1.2.3 | B27: =+B7 -> Terminales 30 kV | C27: =+C7 -> ud | D27: =+D7 -> 0 | E27: =+'PRESUPUESTO P'!E32 -> 220 | F27: =D27*E27 -> 0
A28: 1.2.4 | B28: =+B8 -> Terminales 220 kV | C28: =+C8 -> ud | D28: =+D8 -> 0 | E28: =+'PRESUPUESTO P'!E33 -> 2600 | F28: =D28*E28 -> 0
A29: 1.2.5 | B29: =+B9 -> Autoválvulas 220 kV | C29: =+C9 -> ud | D29: =+D9 -> 0 | E29: =+'PRESUPUESTO P'!E34 -> 1300 | F29: =D29*E29 -> 0
A30: 1.2.6 | B30: =+B10 -> Cámaras de empalmes 30 kV | C30: =+C10 -> ud | D30: =+D10 -> 0 | E30: =+'PRESUPUESTO P'!E35 -> 400 | F30: =D30*E30 -> 0
A31: 1.2.7 | B31: =+B11 -> Cámaras de empalmes 220 kV | C31: =+C11 -> ud | D31: =+D11 -> 0 | E31: =+'PRESUPUESTO P'!E36 -> 3100 | F31: =D31*E31 -> 0
A32: 1.2.8 | B32: =+B12 -> Empalmes 30 kV | C32: =+C12 -> ud | D32: =+D12 -> 0 | E32: =+'PRESUPUESTO P'!E37 -> 300 | F32: =D32*E32 -> 0
A33: 1.2.9 | B33: =+B13 -> Empalmes 220 kV | C33: =+C13 -> ud | D33: =+D13 -> 0 | E33: =+'PRESUPUESTO P'!E38 -> 2500 | F33: =D33*E33 -> 0
A34: 1.2.10 | B34: =+B14 -> Caja de puesta a tierra 30 kV | C34: =+C14 -> ud | D34: =+D14 -> 0 | E34: =+'PRESUPUESTO P'!E39 -> 220 | F34: =D34*E34 -> 0
A35: 1.2.11 | B35: =+B15 -> Caja de puesta a tierra 220 kV | C35: =+C15 -> ud | D35: =+D15 -> 0 | E35: =+'PRESUPUESTO P'!E41 -> 900 | F35: =D35*E35 -> 0
A36: 1.2.12 | B36: =+B16 -> Pequeño material p.a.t pantallas | C36: =+C16 -> ud | D36: =+D16 -> 0 | E36: =+'PRESUPUESTO P'!E42 -> 400 | F36: =D36*E36 -> 0
A37: 1.2.13 | B37: =+B17 -> Cable comunicaciones FO ccto 30 kV | C37: =+C17 -> m | D37: =+D17 -> 0 | E37: =+'PRESUPUESTO P'!E43 -> 1.9 | F37: =D37*E37 -> 0
A38: 1.2.14 | B38: =+B18 -> Cable comunicaciones FO ccto 220 kV | C38: =+C18 -> m | D38: =+D18 -> 0 | E38: =+'PRESUPUESTO P'!E44 -> 2.8 | F38: =D38*E38 -> 0
A39: 1.2.15 | B39: =+B19 -> Cajas empalme FO FO ccto 30 kV | C39: =+C19 -> ud | D39: =+D19 -> 0 | E39: =+'PRESUPUESTO P'!E45 -> 400 | F39: =D39*E39 -> 0
A40: 1.2.16 | B40: =+B20 -> Cajas empalme FO FO ccto 220 kV | C40: =+C20 -> ud | D40: =+D20 -> 0 | E40: =+'PRESUPUESTO P'!E46 -> 600 | F40: =D40*E40 -> 0
A41: TOTAL CAPÍTULO 1.2.- | F41: =SUM(F25:F40) -> 0
A43: CAPÍTULO 1.3. OBRA CIVIL LÍNEA SUBTERRÁNEA
...

Sheet PRESUPUESTO TTMM 3 no hay
A2: CAPÍTULO 1. LÍNEA SUBTERRÁNEA
A3: CAPÍTULO 1.1 MATERIALES LÍNEA SUBTERRÁNEA
A4: Partida | B4: Concepto | C4: Ud. | D4: Cantidad | E4: Precio Ud | F4: Importe (€)
A5: 1.1.1 | B5: Cable aislado 30 kV | C5: m | D5: =+'PRESUPUESTO P'!J5 -> 0 | E5: =+'PRESUPUESTO P'!E5 -> 4 | F5: =D5*E5 -> 0
A6: 1.1.2 | B6: Cable aislado 220 kV | C6: m | D6: =+'PRESUPUESTO P'!J7 -> 0 | E6: =+'PRESUPUESTO P'!E7 -> 120 | F6: =D6*E6 -> 0
A7: 1.1.3 | B7: Terminales 30 kV | C7: ud | D7: =+'PRESUPUESTO P'!J9 -> 0 | E7: =+'PRESUPUESTO P'!E9 -> 160 | F7: =D7*E7 -> 0
A8: 1.1.4 | B8: Terminales 220 kV | C8: ud | D8: =+'PRESUPUESTO P'!J10 -> 0 | E8: =+'PRESUPUESTO P'!E10 -> 7000 | F8: =D8*E8 -> 0
A9: 1.1.5 | B9: Autoválvulas 220 kV | C9: ud | D9: =+'PRESUPUESTO P'!J11 -> 0 | E9: =+'PRESUPUESTO P'!E11 -> 3300 | F9: =D9*E9 -> 0
A10: 1.1.6 | B10: Cámaras de empalmes 30 kV | C10: ud | D10: =+'PRESUPUESTO P'!J12 -> 0 | E10: =+'PRESUPUESTO P'!E12 -> 300 | F10: =D10*E10 -> 0
A11: 1.1.7 | B11: Cámaras de empalmes 220 kV | C11: ud | D11: =+'PRESUPUESTO P'!J13 -> 0 | E11: =+'PRESUPUESTO P'!E13 -> 950 | F11: =D11*E11 -> 0
A12: 1.1.8 | B12: Empalmes 30 kV | C12: ud | D12: =+'PRESUPUESTO P'!J14 -> 0 | E12: =+'PRESUPUESTO P'!E14 -> 180 | F12: =D12*E12 -> 0
A13: 1.1.9 | B13: Empalmes 220 kV | C13: ud | D13: =+'PRESUPUESTO P'!J15 -> 0 | E13: =+'PRESUPUESTO P'!E15 -> 5000 | F13: =D13*E13 -> 0
A14: 1.1.10 | B14: Caja de puesta a tierra 30 kV | C14: ud | D14: =+'PRESUPUESTO P'!J16 -> 0 | E14: =+'PRESUPUESTO P'!E16 -> 640 | F14: =D14*E14 -> 0
A15: 1.1.11 | B15: Caja de puesta a tierra 220 kV | C15: ud | D15: =+'PRESUPUESTO P'!J18 -> 0 | E15: =+'PRESUPUESTO P'!E18 -> 3200 | F15: =D15*E15 -> 0
A16: 1.1.12 | B16: Pequeño material p.a.t pantallas | C16: ud | D16: =+'PRESUPUESTO P'!J19 -> 0 | E16: =+'PRESUPUESTO P'!E19 -> 1000 | F16: =D16*E16 -> 0
A17: 1.1.13 | B17: Cable comunicaciones FO ccto 30 kV | C17: m | D17: =+'PRESUPUESTO P'!J20 -> 0 | E17: =+'PRESUPUESTO P'!E20 -> 1 | F17: =D17*E17 -> 0
A18: 1.1.14 | B18: Cable comunicaciones FO ccto 220 kV | C18: m | D18: =+'PRESUPUESTO P'!J21 -> 0 | E18: =+'PRESUPUESTO P'!E21 -> 1.2 | F18: =D18*E18 -> 0
A19: 1.1.15 | B19: Cajas empalme FO FO ccto 30 kV | C19: ud | D19: =+'PRESUPUESTO P'!J22 -> 0 | E19: =+'PRESUPUESTO P'!E22 -> 300 | F19: =D19*E19 -> 0
A20: 1.1.16 | B20: Cajas empalme FO FO ccto 220 kV | C20: ud | D20: =+'PRESUPUESTO P'!J23 -> 0 | E20: =+'PRESUPUESTO P'!E23 -> 300 | F20: =D20*E20 -> 0
A21: TOTAL CAPÍTULO 1.1.- | F21: =SUM(F5:F20) -> 0
A23: CAPÍTULO 1.2. MONTAJE LÍNEA SUBTERRÁNEA
A24: Partida | B24: Concepto | C24: Ud. | D24: Cantidad | E24: Precio Ud | F24: Importe (€)
A25: 1.2.1 | B25: =+B5 -> Cable aislado 30 kV | C25: =+C5 -> m | D25: =+D5 -> 0 | E25: =+'PRESUPUESTO P'!E28 -> 1.1 | F25: =D25*E25 -> 0
A26: 1.2.2 | B26: =+B6 -> Cable aislado 220 kV | C26: =+C6 -> m | D26: =+D6 -> 0 | E26: =+'PRESUPUESTO P'!E30 -> 6.5 | F26: =D26*E26 -> 0
A27: 1.2.3 | B27: =+B7 -> Terminales 30 kV | C27: =+C7 -> ud | D27: =+D7 -> 0 | E27: =+'PRESUPUESTO P'!E32 -> 220 | F27: =D27*E27 -> 0
A28: 1.2.4 | B28: =+B8 -> Terminales 220 kV | C28: =+C8 -> ud | D28: =+D8 -> 0 | E28: =+'PRESUPUESTO P'!E33 -> 2600 | F28: =D28*E28 -> 0
A29: 1.2.5 | B29: =+B9 -> Autoválvulas 220 kV | C29: =+C9 -> ud | D29: =+D9 -> 0 | E29: =+'PRESUPUESTO P'!E34 -> 1300 | F29: =D29*E29 -> 0
A30: 1.2.6 | B30: =+B10 -> Cámaras de empalmes 30 kV | C30: =+C10 -> ud | D30: =+D10 -> 0 | E30: =+'PRESUPUESTO P'!E35 -> 400 | F30: =D30*E30 -> 0
A31: 1.2.7 | B31: =+B11 -> Cámaras de empalmes 220 kV | C31: =+C11 -> ud | D31: =+D11 -> 0 | E31: =+'PRESUPUESTO P'!E36 -> 3100 | F31: =D31*E31 -> 0
A32: 1.2.8 | B32: =+B12 -> Empalmes 30 kV | C32: =+C12 -> ud | D32: =+D12 -> 0 | E32: =+'PRESUPUESTO P'!E37 -> 300 | F32: =D32*E32 -> 0
A33: 1.2.9 | B33: =+B13 -> Empalmes 220 kV | C33: =+C13 -> ud | D33: =+D13 -> 0 | E33: =+'PRESUPUESTO P'!E38 -> 2500 | F33: =D33*E33 -> 0
A34: 1.2.10 | B34: =+B14 -> Caja de puesta a tierra 30 kV | C34: =+C14 -> ud | D34: =+D14 -> 0 | E34: =+'PRESUPUESTO P'!E39 -> 220 | F34: =D34*E34 -> 0
A35: 1.2.11 | B35: =+B15 -> Caja de puesta a tierra 220 kV | C35: =+C15 -> ud | D35: =+D15 -> 0 | E35: =+'PRESUPUESTO P'!E41 -> 900 | F35: =D35*E35 -> 0
A36: 1.2.12 | B36: =+B16 -> Pequeño material p.a.t pantallas | C36: =+C16 -> ud | D36: =+D16 -> 0 | E36: =+'PRESUPUESTO P'!E42 -> 400 | F36: =D36*E36 -> 0
A37: 1.2.13 | B37: =+B17 -> Cable comunicaciones FO ccto 30 kV | C37: =+C17 -> m | D37: =+D17 -> 0 | E37: =+'PRESUPUESTO P'!E43 -> 1.9 | F37: =D37*E37 -> 0
A38: 1.2.14 | B38: =+B18 -> Cable comunicaciones FO ccto 220 kV | C38: =+C18 -> m | D38: =+D18 -> 0 | E38: =+'PRESUPUESTO P'!E44 -> 2.8 | F38: =D38*E38 -> 0
A39: 1.2.15 | B39: =+B19 -> Cajas empalme FO FO ccto 30 kV | C39: =+C19 -> ud | D39: =+D19 -> 0 | E39: =+'PRESUPUESTO P'!E45 -> 400 | F39: =D39*E39 -> 0
A40: 1.2.16 | B40: =+B20 -> Cajas empalme FO FO ccto 220 kV | C40: =+C20 -> ud | D40: =+D20 -> 0 | E40: =+'PRESUPUESTO P'!E46 -> 600 | F40: =D40*E40 -> 0
A41: TOTAL CAPÍTULO 1.2.- | F41: =SUM(F25:F40) -> 0
A43: CAPÍTULO 1.3. OBRA CIVIL LÍNEA SUBTERRÁNEA
...

Sheet EGR 1-copiar en word 0 EGR
B2: GESTION DE RESIDUOS DE CONSTRUCCIÓN Y DEMOLICIÓN (RCD)
B4: Estimación de residuos en OBRA NUEVA: | C4: ZANJAS BT-MT-AT | H4: Para zanjas nuevas suponemos que un 20% de la tierra no se reutiliza en tapar la zanja, y que de éste 20% un 10% es de residuos Nivel II.
B6: Longitud de zanjas | C6: 0 | D6: m
B7: Ancho de zanjas | C7: 0 | D7: m
B8: Profundidad de zanjas | C8: 0 | D8: m
B9: Volumen total de zanjas | C9: =C6*C7*C8 -> 0 | D9: m²
B10: Volumen total de residuos | C10: =0.2*C9 -> 0 | D10: m³
B11: Volumen de tierras sobrantes | C11: =0.9*C10 -> 0 | D11: m³
B12: Volumen de RCDs Nivel II | C12: =0.1*C10 -> 0 | D12: m³
B15: Estimación de residuos en OBRA NUEVA: | C15: ZANJAS BT-MT-AT | G15: 30 kV
B17: Longitud de zanjas | C17: =+'2.- datos subt'!B6 -> 2206 | D17: m
B18: Ancho de zanjas | C18: 1.356 | D18: m
B19: Profundidad de zanjas | C19: 1.47 | D19: m
B20: Volumen total de zanjas | C20: =C17*C18*C19 -> 4397.2639 | D20: m²
B21: Volumen total de residuos | C21: =0.2*C20 -> 879.45278 | D21: m³
B22: Volumen de tierras sobrantes | C22: =0.9*C21 -> 791.50751 | D22: m³
B23: Volumen de RCDs Nivel II | C23: =0.1*C21 -> 87.945278 | D23: m³
B26: Estimación de residuos en OBRA NUEVA: | C26: ZANJAS BT-MT-AT | G26: 220 kV
B28: Longitud de zanjas | C28: =+'2.- datos subt'!B25 -> 430.47 | D28: m
B29: Ancho de zanjas | C29: 1.2 | D29: m
B30: Profundidad de zanjas | C30: 1.825 | D30: m
B31: Volumen total de zanjas | C31: =C28*C29*C30 -> 942.7293 | D31: m²
B32: Volumen total de residuos | C32: =0.2*C31 -> 188.54586 | D32: m³
B33: Volumen de tierras sobrantes | C33: =0.9*C32 -> 169.69127 | D33: m³
B34: Volumen de RCDs Nivel II | C34: =0.1*C32 -> 18.854586 | D34: m³
B37: Estimación de residuos en OBRA NUEVA: | C37: ZANJAS BT-MT-AT
B39: Longitud de zanjas | C39: 0 | D39: m
B40: Ancho de zanjas | C40: 0 | D40: m
B41: Profundidad de zanjas | C41: 0 | D41: m
B42: Volumen total de zanjas | C42: =C39*C40*C41 -> 0 | D42: m²
B43: Volumen total de residuos | C43: =0.2*C42 -> 0 | D43: m³
B44: Volumen de tierras sobrantes | C44: =0.9*C43 -> 0 | D44: m³
B45: Volumen de RCDs Nivel II | C45: =0.1*C43 -> 0 | D45: m³
B48: Estimación de residuos en OBRA NUEVA: | C48: CÁMARAS DE EMPALME | H48: Para arquetas suponemos que un 80% de la tierra no se reutiliza en tapar la zanja, y que de éste 80% un 10% es de residuos Nivel II.
B50: Numero de cámaras de empalme | C50: =+'2.- datos subt'!B14+'2.- datos subt'!B31 -> 0 | D50: ud
B51: Longitud de la cámara de empalme | C51: 14 | D51: m
B52: Ancho de la cámara de empalme | C52: 3 | D52: m
B53: Profundidad de la cámara de empalme | C53: 2 | D53: m
B54: Volumen total de las cámaras de empalme | C54: =C50*C51*C53*C52 -> 0 | D54: m³
B55: Volumen total de residuos | C55: =0.8*C54 -> 0 | D55: m³
...

Sheet EGR2 2--copiar en word 1 EGR
B2: GESTION DE RESIDUOS DE CONSTRUCCIÓN Y DEMOLICIÓN (RCD)
B4: Estimación de residuos Total:
B6: Volumen total de resíduos Nivel II | C6: ='EGR 1-copiar en word 0 EGR'!C12+'EGR 1-copiar en word 0 EGR'!C23+'EGR 1-copiar en word 0 EGR'!C34+'EGR 1-copiar en word 0 EGR'!C45+'EGR 1-copiar en word 0 EGR'!C57+'EGR 1-copiar en word 0 EGR'!C65+'EGR 1-copiar en word 0 EGR'!C76+'EGR 1-copiar en word 0 EGR'!C83+'EGR 1-copiar en word 0 EGR'!C97+'EGR 1-copiar en word 0 EGR'!C104 -> 106.79986 | D6: m³
B7: Densidad tipo (entre 0,5 y 1,5 T/m³) | C7: 1.1 | D7: Tm/m³
B8: Toneladas de residuos Nivel II | C8: =C6*C7 -> 117.47985 | D8: Tm
B10: Volumen de tierras sobrantes Nivel I | C10: ='EGR 1-copiar en word 0 EGR'!C11+'EGR 1-copiar en word 0 EGR'!C22+'EGR 1-copiar en word 0 EGR'!C33++'EGR 1-copiar en word 0 EGR'!C44+'EGR 1-copiar en word 0 EGR'!C56+'EGR 1-copiar en word 0 EGR'!C64+'EGR 1-copiar en word 0 EGR'!C75+'EGR 1-copiar en word 0 EGR'!C82+'EGR 1-copiar en word 0 EGR'!C96+'EGR 1-copiar en word 0 EGR'!C103 -> 961.19878 | D10: m³
B11: Presupuesto estimado de la obra | C11: =+'PRESUPUESTO P'!C160+'PRESUPUESTO P'!C165 -> 423703.71 | D11: €
B12: Presupuesto de movimiento de tierras en proyecto | C12: =0.015*C11 -> 6355.5556 | D12: €
B14: A.1.: RCDs Nivel I
D15: Tm | E15: d | F15: V
B16: Evaluación teórica del peso por tipología de RDC | D16: Toneladas de RDC | E16: Densidad tipo (entre 1,5 y 0,5) | F16: m³ Volumen de Tierras
B17: 1. TIERRAS Y PÉTREOS DE LA EXCAVACIÓN
B18: Tierras y pétreos procedentes de la excavación estimados directamente desde los datos de proyecto | D18: =F18*E18 -> 1441.7982 | E18: 1.5 | F18: =C10 -> 961.19878
B20: A.2.: RCDs Nivel II
C21: % | D21: Tm | E21: d | F21: V
B22: Evaluación teórica del peso por tipología de RDC | C22: % de peso | D22: Toneladas de cada tipo de RDC | E22: Densidad tipo (entre 1,5 y 0,5) | F22: m³ Volumen de Residuos
B23: RCD: Naturaleza no pétrea
B24: 1. Asfalto | C24: 0.05 | D24: =$C$8*C24 -> 5.8739925 | E24: 1.3 | F24: =D24/E24 -> 4.5184558
B25: 2. Madera | C25: 0.04 | D25: =$C$8*C25 -> 4.699194 | E25: 0.6 | F25: =D25/E25 -> 7.8319901
B26: 3. Metales | C26: 0.025 | D26: =$C$8*C26 -> 2.9369963 | E26: 1.5 | F26: =D26/E26 -> 1.9579975
B27: 4. Papel | C27: 0.003 | D27: =$C$8*C27 -> 0.35243955 | E27: 0.9 | F27: =D27/E27 -> 0.3915995
B28: 5. Plástico | C28: 0.015 | D28: =$C$8*C28 -> 1.7621978 | E28: 0.9 | F28: =D28/E28 -> 1.9579975
B29: 6. Vidrio | C29: 0.005 | D29: =$C$8*C29 -> 0.58739925 | E29: 1.5 | F29: =D29/E29 -> 0.3915995
B30: 7. Yeso | C30: 0.002 | D30: =$C$8*C30 -> 0.2349597 | E30: 1.2 | F30: =D30/E30 -> 0.19579975
B31: TOTAL estimación | C31: =SUM(C24:C30) -> 0.14 | D31: =$C$8*C31 -> 16.447179 | F31: =SUM(F24:F30) -> 17.24544
B33: RCD: Naturaleza pétrea
B34: 1. Arena Grava y otros áridos | C34: 0.04 | D34: =$C$8*C34 -> 4.699194 | E34: 1.5 | F34: =D34/E34 -> 3.132796
B35: 2. Hormigón | C35: 0.12 | D35: =$C$8*C35 -> 14.097582 | E35: 1.5 | F35: =D35/E35 -> 9.3983881
B36: 3. Ladrillos , azulejos y otros cerámicos | C36: 0.54 | D36: =$C$8*C36 -> 63.439119 | E36: 1.5 | F36: =D36/E36 -> 42.292746
B37: 4. Piedra | C37: 0.05 | D37: =$C$8*C37 -> 5.8739925 | E37: 1.5 | F37: =D37/E37 -> 3.915995
B38: TOTAL estimación | C38: =SUM(C34:C37) -> 0.75 | D38: =$C$8*C38 -> 88.109888 | F38: =SUM(F34:F37) -> 58.739925
B40: RCD: Potencialmente peligrosos y otros
B41: 1. Basuras | C41: 0.07 | D41: =$C$8*C41 -> 8.2235896 | E41: 0.9 | F41: =D41/E41 -> 9.1373217
B42: 2. Potencialmente peligrosos y otros | C42: 0.04 | D42: =$C$8*C42 -> 4.699194 | E42: 0.5 | F42: =D42/E42 -> 9.3983881
B43: TOTAL estimación | C43: =C41+C42 -> 0.11 | D43: =$C$8*C43 -> 12.922784 | F43: =SUM(F41:F42) -> 18.53571
C44: =C31+C38+C43 -> 1 | D44: =D31+D38+D43 -> 117.47985

Sheet EGR 3-copiar en word 2 EGR
B2: A.1.: RCDs Nivel I
C4: 1. TIERRAS Y PÉTROS DE LA EXCAVACIÓN | F4: Tratamiento | G4: Destino | H4: Cantidad | J4: Porcentajes estimados | M4: esta tabla de copia y pega en la memoria
B5: x | C5: 17 05 04 | D5: Tierras y piedras distintas de las especificadas en el código 17 05 03 | F5: Sin tratamiento esp. | G5: Restauración / Vertedero | H5: =IF(B5="X",'EGR2 2--copiar en word 1 EGR'!D18-H6-H7,0) -> 1441.7982 | J5: Diferencia tipo RCD
C6: 17 05 06 | D6: Lodos de drenaje distintos de los especificados en el código 17 05 06 | F6: Sin tratamiento esp. | G6: Restauración / Vertedero | H6: =IF(B6="X",J6*'EGR2 2--copiar en word 1 EGR'!$D$18,0) -> 0 | J6: 0.15
C7: 17 05 08 | D7: Balasto de vías férreas distinto del especificado en el código 17 05 07 | F7: Sin tratamiento esp. | G7: Restauración / Vertedero | H7: =IF(B7="X",J7*'EGR2 2--copiar en word 1 EGR'!$D$18,0) -> 0 | J7: 0.05
B9: A.2.: RCDs Nivel II
C11: RCD: Naturaleza no pétrea | F11: Tratamiento | G11: Destino | H11: Cantidad
C13: 1. Asfalto
B14: x | C14: 17 03 02 | D14: Mezclas bituminosas distintas a las del código 17 03 01 | F14: Reciclado | G14: Planta de reciclaje RCD | H14: ='EGR2 2--copiar en word 1 EGR'!D24 -> 5.8739925 | J14: Total tipo RCD
C15: 2. Madera
B16: x | C16: 17 02 01 | D16: Madera | F16: Reciclado | G16: Gestor autorizado RNPs | H16: ='EGR2 2--copiar en word 1 EGR'!D25 -> 4.699194 | J16: Total tipo RCD
C17: 3. Metales
B18: x | C18: 17 04 01 | D18: Cobre, bronce, latón | F18: Reciclado | G18: Gestor autorizado RNPs | H18: =IF(B18="X",J18*'EGR2 2--copiar en word 1 EGR'!D26,0) -> 0.29369963 | J18: 0.1
B19: x | C19: 17 04 02 | D19: Aluminio | F19: Reciclado | H19: =IF(B19="X",J19*'EGR2 2--copiar en word 1 EGR'!D27,0) -> 0.024670769 | J19: 0.07
C20: 17 04 03 | D20: Plomo | H20: =IF(B20="X",J20*'EGR2 2--copiar en word 1 EGR'!D28,0) -> 0 | J20: 0.05
C21: 17 04 04 | D21: Zinc | H21: =IF(B21="X",J21*'EGR2 2--copiar en word 1 EGR'!D29,0) -> 0 | J21: 0.15
B22: x | C22: 17 04 05 | D22: Hierro y Acero | F22: Reciclado | H22: =IF(B22="X",'EGR2 2--copiar en word 1 EGR'!D34-H18-H19-H20-H21-H23-H24-H25,0) -> 4.3808236 | J22: Diferencia tipo RCD
C23: 17 04 06 | D23: Estaño | H23: =IF(B23="X",J23*'EGR2 2--copiar en word 1 EGR'!D31,0) -> 0 | J23: 0.1
C24: 17 04 06 | D24: Metales mezclados | F24: Reciclado | H24: =IF(B24="X",J24*'EGR2 2--copiar en word 1 EGR'!D32,0) -> 0 | J24: 0.25
C25: 17 04 11 | D25: Cables distintos de los especificados en el código 17 04 10 | F25: Reciclado | H25: =IF(B25="X",J25*'EGR2 2--copiar en word 1 EGR'!D33,0) -> 0 | J25: 0.1
C26: 4. Papel
B27: x | C27: 20 01 01 | D27: Papel | F27: Reciclado | G27: Gestor autorizado RNPs | H27: ='EGR2 2--copiar en word 1 EGR'!D27 -> 0.35243955 | J27: Total tipo RCD
C28: 5. Plástico
B29: x | C29: 17 02 03 | D29: Plástico | F29: Reciclado | G29: Gestor autorizado RNPs | H29: ='EGR2 2--copiar en word 1 EGR'!D28 -> 1.7621978 | J29: Total tipo RCD
C30: 6. Vidrio
C31: 17 02 02 | D31: Vidrio | F31: Reciclado | G31: Gestor autorizado RNPs | H31: ='EGR2 2--copiar en word 1 EGR'!D29 -> 0.58739925 | J31: Total tipo RCD
C32: 7. Yeso
C33: 17 08 02 | D33: Materiales de construcción a partir de yeso distintos a los del código 17 08 01 | F33: Reciclado | G33: Gestor autorizado RNPs | H33: ='EGR2 2--copiar en word 1 EGR'!D30 -> 0.2349597 | J33: Total tipo RCD
C36: RCD: Naturaleza pétrea | F36: Tratamiento | G36: Destino | H36: Cantidad
C38: 1. Arena Grava y otros áridos
B39: x | C39: 01 04 08 | D39: Residuos de grava y rocas trituradas distintos de los mencionados en el código 01 04 07 | F39: Reciclado | G39: Planta de reciclaje RCD | H39: =IF(B39="X",J39*'EGR2 2--copiar en word 1 EGR'!D34,0) -> 1.1747985 | J39: 0.25
B40: x | C40: 01 04 09 | D40: Residuos de arena y arcilla | F40: Reciclado | G40: Planta de reciclaje RCD | H40: =IF(B40="X",'EGR2 2--copiar en word 1 EGR'!D34-H39,0) -> 3.5243955 | J40: Diferencia tipo RCD
C42: 2. Hormigón
B43: x | C43: 17 01 01 | D43: Hormigón | F43: Reciclado / Vertedero | G43: Planta de reciclaje RCD | H43: ='EGR2 2--copiar en word 1 EGR'!D35 -> 14.097582 | J43: Total tipo RCD
C45: 3. Ladrillos , azulejos y otros cerámicos
C46: 17 01 02 | D46: Ladrillos | F46: Reciclado | G46: Planta de reciclaje RCD | H46: =IF(B46="X",J46*'EGR2 2--copiar en word 1 EGR'!D36,0) -> 0 | J46: 0.35
C47: 17 01 03 | D47: Tejas y materiales cerámicos | F47: Reciclado | G47: Planta de reciclaje RCD | H47: =IF(B47="X",'EGR2 2--copiar en word 1 EGR'!D36-'EGR 3-copiar en word 2 EGR'!H46-'EGR 3-copiar en word 2 EGR'!H48,0) -> 0 | J47: Diferencia tipo RCD
C48: 17 01 07 | D48: Mezclas de hormigón, ladrillos, tejas y materiales cerámicos distintas de las especificadas en el código 1 7 01 06. | F48: Reciclado / Vertedero | G48: Planta de reciclaje RCD | H48: =IF(B48="X",J48*'EGR2 2--copiar en word 1 EGR'!D38,0) -> 0 | J48: 0.25
C50: 4. Piedra
B51: x | C51: 17 09 04 | D51: RDCs mezclados distintos a los de los códigos 17 09 01, 02 y 03 | F51: Reciclado | H51: ='EGR2 2--copiar en word 1 EGR'!D37 -> 5.8739925 | J51: Total tipo RCD
...

Sheet EGR 4-copiar en word 3 EGR
B2: A.- ESTIMACIÓN DEL COSTE DE TRATAMIENTO DE LOS RCDs
B4: Tipología RCDs | C4: Estimación (m³) | D4: Precio gestión en Planta / Vertedero / Cantera / Gestor (€/m³) | E4: Importe (€) | F4: Importe mínimo(€) | G4: % del presupuesto de Obra
B5: A1 RCDs Nivel I
B6: Tierras y pétreos de la excavación | C6: ='EGR2 2--copiar en word 1 EGR'!F18 -> 961.19878 | D6: 8 | E6: =C6*D6 -> 7689.5902 | F6: =MAX(E6,8) -> 7689.5902 | G6: =F6/'EGR2 2--copiar en word 1 EGR'!$C$11*100 -> 1.8148508
G7: =G6 -> 1.8148508
B9: A2 RCDs Nivel II
B10: RCDs Naturaleza Pétrea | C10: ='EGR2 2--copiar en word 1 EGR'!F38 -> 58.739925 | D10: 20 | E10: =C10*D10 -> 1174.7985 | F10: =MAX(E10,20) -> 1174.7985 | G10: =F10/'EGR2 2--copiar en word 1 EGR'!$C$11*100 -> 0.27726888
B11: RCDs Naturaleza No Pétrea (metales) | C11: ='EGR2 2--copiar en word 1 EGR'!F26 -> 1.9579975 | D11: 105 | E11: =C11*D11 -> 205.58974 | F11: =E11 -> 205.58974 | G11: =F11/'EGR2 2--copiar en word 1 EGR'!$C$11*100 -> 0.048522053
B12: RCDs Naturaleza No Pétrea (resto) | C12: ='EGR2 2--copiar en word 1 EGR'!F31-'EGR 4-copiar en word 3 EGR'!C11 -> 15.287442 | D12: 23 | E12: =C12*D12 -> 351.61117 | F12: =MAX(E12,23) -> 351.61117 | G12: =F12/'EGR2 2--copiar en word 1 EGR'!$C$11*100 -> 0.082985153
B13: RCDs Potencialmente peligrosos | C13: ='EGR2 2--copiar en word 1 EGR'!F43 -> 18.53571 | D13: 30 | E13: =C13*D13 -> 556.07129 | F13: =MAX(E13,30) -> 556.07129 | G13: =F13/'EGR2 2--copiar en word 1 EGR'!$C$11*100 -> 0.1312406
G14: =SUM(G10:G13) -> 0.54001668
B16: B.- RESTO DE COSTES DE GESTIÓN
B17: B1.- % Presupuesto hasta cubrir RCD Nivel I | E17: =G17/100*'EGR2 2--copiar en word 1 EGR'!$C$11 -> 0 | F17: =G17/100*'EGR2 2--copiar en word 1 EGR'!$C$11 -> 0 | G17: =IF(G7<0.2,0.2-G7,0) -> 0
B18: B2.- % Presupuesto hasta cubrir RCD Nivel II | E18: =G18/100*'EGR2 2--copiar en word 1 EGR'!$C$11 -> 0 | F18: =G18/100*'EGR2 2--copiar en word 1 EGR'!$C$11 -> 0 | G18: =IF(G14<0.2,0.2-G14,0) -> 0
B19: B3.- % Presupuesto de Obra por costes de gestión, alquileres, etc… | E19: =G19/100*'EGR2 2--copiar en word 1 EGR'!$C$11 -> 423.70371 | F19: =G19/100*'EGR2 2--copiar en word 1 EGR'!$C$11 -> 423.70371 | G19: 0.1
B21: TOTAL PRESUPUESTO PLAN GESTION RCDs | E21: =E6+E10+E11+E12+E13+E17+E18+E19 -> 10401.365 | F21: =F6+F10+F11+F12+F13+F17+F18+F19 -> 10401.365 | G21: =G7+G14+G17+G18+G19 -> 2.4548675
D30: =24/70 -> 0.34285714

Sheet ESS 1-input-copiar en word ESS
A1: PROCESO | B1: 1.- ENTRADA DATOS VERDES
B2: 2.- COPIAR EL PRESUPUESTO AL WORD
H5: Días totales | I5: Nº trabajadores (máximo) | J5: Duración estimada (meses) | K5: Fracción estimada anual | L5: Los días totales se estiman del archivo Excel de planificación. Se estiman 3 cuadrillas de 10 trabajadores
A6: Prevención y formación | H6: =+J6*20 -> 80 | I6: 10 | J6: 4 | K6: =+ROUNDUP(J6/12,2) -> 0.34
A8: Nº DE ORDEN | B8: DESCRIPCION | C8: HORAS - HOMBRE – MES | D8: PRECIO UNIDAD | E8: FRACCIÓN ESTIMADA | F8: COSTE (€)
A10: 1 | B10: Asistencia técnica, inspecciones, informes… | C10: 14 | D10: 57.33 | E10: =+J6 -> 4 | F10: =+C10*D10*E10 -> 3210.48
A11: 2 | B11: Reuniones de seguridad | C11: 0.5 | D11: 344.01 | E11: =+J6 -> 4 | F11: =+C11*D11*E11 -> 688.02
A12: 3 | B12: Formación | C12: 0.5 | D12: 573.35 | E12: =+J6 -> 4 | F12: =+C12*D12*E12 -> 1146.7
A13: Subtotal | F13: =SUM(F10:F12) -> 5045.2
A15: Servicio médico
A17: Nº DE ORDEN | B17: DESCRIPCION | C17: Nº DE OPERARIOS | D17: PRECIO UNIDAD | E17: FRACCIÓN ESTIMADA | F17: COSTE (€)
A19: 1 | B19: Reconocimiento médico | C19: =+I6 -> 10 | D19: 57.33 | E19: =+K6 -> 0.34 | F19: =+C19*D19*E19 -> 194.922
A20: Subtotal | F20: =+F19 -> 194.922
A22: Protecciones colectivas
A24: Nº DE ORDEN | B24: DESCRIPCION | C24: DOTACION ANUAL OPERARIO | D24: PRECIO UNIDAD (€) | E24: Nº DE OPERARIOS PREVISTOS | F24: FRACCIÓN ESTIMADA | G24: COSTE (€)
A26: 1 | B26: Cerramientos/vallas de obra | C26: 0.1 | D26: 7166.82 | E26: =I6 -> 10 | F26: =+K6/3 -> 0.11333333 | G26: =C26*D26*E26*F26 -> 812.2396
A27: 2 | B27: Barandillas | C27: 0.25 | D27: 86 | E27: =I6 -> 10 | F27: =+K6 -> 0.34 | G27: =+C27*D27*E27*F27 -> 73.1
A28: 3 | B28: Señalización zona de trabajo | C28: 0.25 | D28: 28.67 | E28: =I6 -> 10 | F28: =+K6 -> 0.34 | G28: =+C28*D28*E28*F28 -> 24.3695
A29: 4 | B29: Cintas de balizamiento | C29: 1 | D29: 21.5 | E29: =I6 -> 10 | F29: =+K6 -> 0.34 | G29: =+C29*D29*E29*F29 -> 73.1
A30: 5 | B30: Vallas metálicas | C30: 0.5 | D30: 57.33 | E30: =I6 -> 10 | F30: =+K6/3 -> 0.11333333 | G30: =+C30*D30*E30*F30 -> 32.487
A31: 6 | B31: Andamios | C31: 0.15 | D31: 2866.73 | E31: =I6 -> 10 | F31: =+K6 -> 0.34 | G31: =+C31*D31*E31*F31 -> 1462.0323
A32: 7 | B32: Chapa protección huecos | C32: 0.25 | D32: 95.56 | E32: =I6 -> 10 | F32: =+K6 -> 0.34 | G32: =+C32*D32*E32*F32 -> 81.226
A33: 8 | B33: Escaleras de mano | C33: 0.5 | D33: 114.67 | E33: =I6 -> 10 | F33: =+K6 -> 0.34 | G33: =+C33*D33*E33*F33 -> 194.939
A34: 9 | B34: Protección ferralla (setas plástico) | C34: 30 | D34: 0.36 | E34: =I6 -> 10 | F34: =+K6 -> 0.34 | G34: =+C34*D34*E34*F34 -> 36.72
A35: 10 | B35: Extintores portátiles | C35: 0.25 | D35: 32 | E35: =I6 -> 10 | F35: =+K6 -> 0.34 | G35: =+C35*D35*E35*F35 -> 27.2
A36: 11 | B36: Líneas de vida | C36: 0.5 | D36: 226.95 | E36: =I6 -> 10 | F36: =+K6 -> 0.34 | G36: =+C36*D36*E36*F36 -> 385.815
A37: Subtotal | G37: =SUM(G26:G36) -> 3203.2284
A39: Protecciones individuales
A41: Nº DE ORDEN | B41: DESCRIPCION | C41: DOTACION ANUAL OPERARIO | D41: PRECIO UNIDAD (€) | E41: Nº DE OPERARIOS PREVISTOS | F41: FRACCIÓN ESTIMADA | G41: COSTE (€)
A43: 1 | B43: Casco seguridad | C43: 1.25 | D43: 8.6 | E43: =+$I$6 -> 10 | F43: =+$K$6 -> 0.34 | G43: =C43*D43*E43*F43 -> 36.55
A44: 2 | B44: Gafas contra impactos | C44: 1 | D44: 43 | E44: =+$I$6 -> 10 | F44: =+$K$6 -> 0.34 | G44: =C44*D44*E44*F44 -> 146.2
A45: 3 | B45: Gafas ambientes pulvígenos | C45: 1 | D45: 43 | E45: =+$I$6 -> 10 | F45: =+$K$6 -> 0.34 | G45: =C45*D45*E45*F45 -> 146.2
A46: 4 | B46: Gafas soldadura autógena | C46: 1 | D46: 43 | E46: =+$I$6 -> 10 | F46: =+$K$6 -> 0.34 | G46: =C46*D46*E46*F46 -> 146.2
A47: 5 | B47: Guantes de trabajo | C47: 12 | D47: 7.17 | E47: =+$I$6 -> 10 | F47: =+$K$6 -> 0.34 | G47: =C47*D47*E47*F47 -> 292.536
A48: 6 | B48: Guantes de goma | C48: 3 | D48: 7.17 | E48: =+$I$6 -> 10 | F48: =+$K$6 -> 0.34 | G48: =C48*D48*E48*F48 -> 73.134
A49: 7 | B49: Guantes aislantes | C49: 1 | D49: 86.15 | E49: =+$I$6 -> 10 | F49: =+$K$6 -> 0.34 | G49: =C49*D49*E49*F49 -> 292.91
A50: 8 | B50: Pantalla arco eléctrico | C50: 1 | D50: 28.67 | E50: =+$I$6 -> 10 | F50: =+$K$6 -> 0.34 | G50: =C50*D50*E50*F50 -> 97.478
A51: 9 | B51: Mascarilla ambientes pulvígenos | C51: 6 | D51: 4.3 | E51: =+$I$6 -> 10 | F51: =+$K$6 -> 0.34 | G51: =C51*D51*E51*F51 -> 87.72
A52: 10 | B52: Protecciones auditivas | C52: 2 | D52: 17.2 | E52: =+$I$6 -> 10 | F52: =+$K$6 -> 0.34 | G52: =C52*D52*E52*F52 -> 116.96
A53: 11 | B53: Manguitos soldador | C53: 1 | D53: 31.06 | E53: =+$I$6 -> 10 | F53: =+$K$6 -> 0.34 | G53: =C53*D53*E53*F53 -> 105.604
...
